<mujoco model="asv_with_ice_random">
  <compiler angle="degree"/>
  <option gravity="0 0 -9.81"/>

  <worldbody>

    <light directional="true" ambient="0.2 0.2 0.2" diffuse="0.8 0.8 0.8" specular="0.3 0.3 0.3" castshadow="false" pos="0 0 4" dir="0 0 -1" name="light0"></light>
    
    <camera name="follow_asv" mode="fixed" target="asv" pos="0 0 10" euler="30 0 0"/>

    <geom type="plane" size="10 5 0.1" rgba="0 0.47 0.74 1"
        contype="0" conaffinity="0"/>
        
    <!-- ASV -->
    <body name="asv" pos="0 0 0">
      <joint name="asv_x" type="slide" axis="1 0 0"/>
      <joint name="asv_y" type="slide" axis="0 1 0"/>
      <joint name="asv_yaw" type="hinge" axis="0 0 1"/>
      
      <geom type="box" size="0.4 0.1 0.05" pos="0 0 0" friction="0.00 0.00 0.00"/>
      
      <geom type="box" size="0.1 0.08 0.05" pos="0.4 0 0"  friction="0.00 0.00 0.00"/>

      <geom type="box" size="0.06 0.06 0.05" pos="0.5 0 0"  friction="0.00 0.00 0.00"/>

      <geom type="box" size="0.03 0.04 0.05" pos="0.56 0 0"  friction="0.00 0.00 0.00"/>

      <geom type="box" size="0.01 0.02 0.05" pos="0.59 0 0"  friction="0.00 0.00 0.00"/>

      <camera name="follow_asv1" mode="track" target="asv" pos="0 0 10" euler="30 0 0"/>
      
    </body>

    <body name="ice_0" pos="-3.67 1.58 0">
      <joint name="ice_0_x" type="slide" axis="1 0 0"/>
      <joint name="ice_0_y" type="slide" axis="0 1 0"/>
      <joint name="ice_0_yaw" type="hinge" axis="0 0 1"/>
      <geom type="box" size="0.1 0.1 0.02" rgba="0.9 0.9 1.0 0.8" friction="0.00 0.00 0.00"/>
    </body>
    <body name="ice_1" pos="-0.52 1.84 0">
      <joint name="ice_1_x" type="slide" axis="1 0 0"/>
      <joint name="ice_1_y" type="slide" axis="0 1 0"/>
      <joint name="ice_1_yaw" type="hinge" axis="0 0 1"/>
      <geom type="box" size="0.1 0.1 0.02" rgba="0.9 0.9 1.0 0.8" friction="0.00 0.00 0.00"/>
    </body>
    <body name="ice_2" pos="-1.46 0.32 0">
      <joint name="ice_2_x" type="slide" axis="1 0 0"/>
      <joint name="ice_2_y" type="slide" axis="0 1 0"/>
      <joint name="ice_2_yaw" type="hinge" axis="0 0 1"/>
      <geom type="box" size="0.1 0.1 0.02" rgba="0.9 0.9 1.0 0.8" friction="0.00 0.00 0.00"/>
    </body>
    <body name="ice_3" pos="-3.18 0.08 0">
      <joint name="ice_3_x" type="slide" axis="1 0 0"/>
      <joint name="ice_3_y" type="slide" axis="0 1 0"/>
      <joint name="ice_3_yaw" type="hinge" axis="0 0 1"/>
      <geom type="box" size="0.1 0.1 0.02" rgba="0.9 0.9 1.0 0.8" friction="0.00 0.00 0.00"/>
    </body>
    <body name="ice_4" pos="-4.15 -1.40 0">
      <joint name="ice_4_x" type="slide" axis="1 0 0"/>
      <joint name="ice_4_y" type="slide" axis="0 1 0"/>
      <joint name="ice_4_yaw" type="hinge" axis="0 0 1"/>
      <geom type="box" size="0.1 0.1 0.02" rgba="0.9 0.9 1.0 0.8" friction="0.00 0.00 0.00"/>
    </body>
    <body name="ice_5" pos="1.66 1.78 0">
      <joint name="ice_5_x" type="slide" axis="1 0 0"/>
      <joint name="ice_5_y" type="slide" axis="0 1 0"/>
      <joint name="ice_5_yaw" type="hinge" axis="0 0 1"/>
      <geom type="box" size="0.1 0.1 0.02" rgba="0.9 0.9 1.0 0.8" friction="0.00 0.00 0.00"/>
    </body>
    <body name="ice_6" pos="2.22 -0.23 0">
      <joint name="ice_6_x" type="slide" axis="1 0 0"/>
      <joint name="ice_6_y" type="slide" axis="0 1 0"/>
      <joint name="ice_6_yaw" type="hinge" axis="0 0 1"/>
      <geom type="box" size="0.1 0.1 0.02" rgba="0.9 0.9 1.0 0.8" friction="0.00 0.00 0.00"/>
    </body>
    <body name="ice_7" pos="3.27 -0.60 0">
      <joint name="ice_7_x" type="slide" axis="1 0 0"/>
      <joint name="ice_7_y" type="slide" axis="0 1 0"/>
      <joint name="ice_7_yaw" type="hinge" axis="0 0 1"/>
      <geom type="box" size="0.1 0.1 0.02" rgba="0.9 0.9 1.0 0.8" friction="0.00 0.00 0.00"/>
    </body>
    <body name="ice_8" pos="3.44 0.24 0">
      <joint name="ice_8_x" type="slide" axis="1 0 0"/>
      <joint name="ice_8_y" type="slide" axis="0 1 0"/>
      <joint name="ice_8_yaw" type="hinge" axis="0 0 1"/>
      <geom type="box" size="0.1 0.1 0.02" rgba="0.9 0.9 1.0 0.8" friction="0.00 0.00 0.00"/>
    </body>
    <body name="ice_9" pos="4.46 -1.99 0">
      <joint name="ice_9_x" type="slide" axis="1 0 0"/>
      <joint name="ice_9_y" type="slide" axis="0 1 0"/>
      <joint name="ice_9_yaw" type="hinge" axis="0 0 1"/>
      <geom type="box" size="0.1 0.1 0.02" rgba="0.9 0.9 1.0 0.8" friction="0.00 0.00 0.00"/>
    </body>
    <body name="ice_10" pos="-3.74 -1.83 0">
      <joint name="ice_10_x" type="slide" axis="1 0 0"/>
      <joint name="ice_10_y" type="slide" axis="0 1 0"/>
      <joint name="ice_10_yaw" type="hinge" axis="0 0 1"/>
      <geom type="box" size="0.1 0.1 0.02" rgba="0.9 0.9 1.0 0.8" friction="0.00 0.00 0.00"/>
    </body>
    <body name="ice_11" pos="-1.33 2.30 0">
      <joint name="ice_11_x" type="slide" axis="1 0 0"/>
      <joint name="ice_11_y" type="slide" axis="0 1 0"/>
      <joint name="ice_11_yaw" type="hinge" axis="0 0 1"/>
      <geom type="box" size="0.1 0.1 0.02" rgba="0.9 0.9 1.0 0.8" friction="0.00 0.00 0.00"/>
    </body>
    <body name="ice_12" pos="3.92 0.50 0">
      <joint name="ice_12_x" type="slide" axis="1 0 0"/>
      <joint name="ice_12_y" type="slide" axis="0 1 0"/>
      <joint name="ice_12_yaw" type="hinge" axis="0 0 1"/>
      <geom type="box" size="0.1 0.1 0.02" rgba="0.9 0.9 1.0 0.8" friction="0.00 0.00 0.00"/>
    </body>
    <body name="ice_13" pos="1.22 0.08 0">
      <joint name="ice_13_x" type="slide" axis="1 0 0"/>
      <joint name="ice_13_y" type="slide" axis="0 1 0"/>
      <joint name="ice_13_yaw" type="hinge" axis="0 0 1"/>
      <geom type="box" size="0.1 0.1 0.02" rgba="0.9 0.9 1.0 0.8" friction="0.00 0.00 0.00"/>
    </body>
    <body name="ice_14" pos="-1.29 -0.60 0">
      <joint name="ice_14_x" type="slide" axis="1 0 0"/>
      <joint name="ice_14_y" type="slide" axis="0 1 0"/>
      <joint name="ice_14_yaw" type="hinge" axis="0 0 1"/>
      <geom type="box" size="0.1 0.1 0.02" rgba="0.9 0.9 1.0 0.8" friction="0.00 0.00 0.00"/>
    </body>
    <body name="ice_15" pos="2.74 1.62 0">
      <joint name="ice_15_x" type="slide" axis="1 0 0"/>
      <joint name="ice_15_y" type="slide" axis="0 1 0"/>
      <joint name="ice_15_yaw" type="hinge" axis="0 0 1"/>
      <geom type="box" size="0.1 0.1 0.02" rgba="0.9 0.9 1.0 0.8" friction="0.00 0.00 0.00"/>
    </body>
    <body name="ice_16" pos="-2.50 -0.97 0">
      <joint name="ice_16_x" type="slide" axis="1 0 0"/>
      <joint name="ice_16_y" type="slide" axis="0 1 0"/>
      <joint name="ice_16_yaw" type="hinge" axis="0 0 1"/>
      <geom type="box" size="0.1 0.1 0.02" rgba="0.9 0.9 1.0 0.8" friction="0.00 0.00 0.00"/>
    </body>
    <body name="ice_17" pos="4.97 -1.11 0">
      <joint name="ice_17_x" type="slide" axis="1 0 0"/>
      <joint name="ice_17_y" type="slide" axis="0 1 0"/>
      <joint name="ice_17_yaw" type="hinge" axis="0 0 1"/>
      <geom type="box" size="0.1 0.1 0.02" rgba="0.9 0.9 1.0 0.8" friction="0.00 0.00 0.00"/>
    </body>
    <body name="ice_18" pos="-2.74 1.37 0">
      <joint name="ice_18_x" type="slide" axis="1 0 0"/>
      <joint name="ice_18_y" type="slide" axis="0 1 0"/>
      <joint name="ice_18_yaw" type="hinge" axis="0 0 1"/>
      <geom type="box" size="0.1 0.1 0.02" rgba="0.9 0.9 1.0 0.8" friction="0.00 0.00 0.00"/>
    </body>
    <body name="ice_19" pos="-3.17 1.45 0">
      <joint name="ice_19_x" type="slide" axis="1 0 0"/>
      <joint name="ice_19_y" type="slide" axis="0 1 0"/>
      <joint name="ice_19_yaw" type="hinge" axis="0 0 1"/>
      <geom type="box" size="0.1 0.1 0.02" rgba="0.9 0.9 1.0 0.8" friction="0.00 0.00 0.00"/>
    </body>
    <body name="ice_20" pos="3.36 -2.26 0">
      <joint name="ice_20_x" type="slide" axis="1 0 0"/>
      <joint name="ice_20_y" type="slide" axis="0 1 0"/>
      <joint name="ice_20_yaw" type="hinge" axis="0 0 1"/>
      <geom type="box" size="0.1 0.1 0.02" rgba="0.9 0.9 1.0 0.8" friction="0.00 0.00 0.00"/>
    </body>
    <body name="ice_21" pos="3.80 -1.00 0">
      <joint name="ice_21_x" type="slide" axis="1 0 0"/>
      <joint name="ice_21_y" type="slide" axis="0 1 0"/>
      <joint name="ice_21_yaw" type="hinge" axis="0 0 1"/>
      <geom type="box" size="0.1 0.1 0.02" rgba="0.9 0.9 1.0 0.8" friction="0.00 0.00 0.00"/>
    </body>
    <body name="ice_22" pos="-1.37 -0.02 0">
      <joint name="ice_22_x" type="slide" axis="1 0 0"/>
      <joint name="ice_22_y" type="slide" axis="0 1 0"/>
      <joint name="ice_22_yaw" type="hinge" axis="0 0 1"/>
      <geom type="box" size="0.1 0.1 0.02" rgba="0.9 0.9 1.0 0.8" friction="0.00 0.00 0.00"/>
    </body>
    <body name="ice_23" pos="-4.69 -0.07 0">
      <joint name="ice_23_x" type="slide" axis="1 0 0"/>
      <joint name="ice_23_y" type="slide" axis="0 1 0"/>
      <joint name="ice_23_yaw" type="hinge" axis="0 0 1"/>
      <geom type="box" size="0.1 0.1 0.02" rgba="0.9 0.9 1.0 0.8" friction="0.00 0.00 0.00"/>
    </body>
    <body name="ice_24" pos="3.10 0.76 0">
      <joint name="ice_24_x" type="slide" axis="1 0 0"/>
      <joint name="ice_24_y" type="slide" axis="0 1 0"/>
      <joint name="ice_24_yaw" type="hinge" axis="0 0 1"/>
      <geom type="box" size="0.1 0.1 0.02" rgba="0.9 0.9 1.0 0.8" friction="0.00 0.00 0.00"/>
    </body>
    <body name="ice_25" pos="4.42 1.09 0">
      <joint name="ice_25_x" type="slide" axis="1 0 0"/>
      <joint name="ice_25_y" type="slide" axis="0 1 0"/>
      <joint name="ice_25_yaw" type="hinge" axis="0 0 1"/>
      <geom type="box" size="0.1 0.1 0.02" rgba="0.9 0.9 1.0 0.8" friction="0.00 0.00 0.00"/>
    </body>
    <body name="ice_26" pos="1.21 -0.75 0">
      <joint name="ice_26_x" type="slide" axis="1 0 0"/>
      <joint name="ice_26_y" type="slide" axis="0 1 0"/>
      <joint name="ice_26_yaw" type="hinge" axis="0 0 1"/>
      <geom type="box" size="0.1 0.1 0.02" rgba="0.9 0.9 1.0 0.8" friction="0.00 0.00 0.00"/>
    </body>
    <body name="ice_27" pos="-0.77 -0.54 0">
      <joint name="ice_27_x" type="slide" axis="1 0 0"/>
      <joint name="ice_27_y" type="slide" axis="0 1 0"/>
      <joint name="ice_27_yaw" type="hinge" axis="0 0 1"/>
      <geom type="box" size="0.1 0.1 0.02" rgba="0.9 0.9 1.0 0.8" friction="0.00 0.00 0.00"/>
    </body>
    <body name="ice_28" pos="4.93 -1.60 0">
      <joint name="ice_28_x" type="slide" axis="1 0 0"/>
      <joint name="ice_28_y" type="slide" axis="0 1 0"/>
      <joint name="ice_28_yaw" type="hinge" axis="0 0 1"/>
      <geom type="box" size="0.1 0.1 0.02" rgba="0.9 0.9 1.0 0.8" friction="0.00 0.00 0.00"/>
    </body>
    <body name="ice_29" pos="3.48 1.18 0">
      <joint name="ice_29_x" type="slide" axis="1 0 0"/>
      <joint name="ice_29_y" type="slide" axis="0 1 0"/>
      <joint name="ice_29_yaw" type="hinge" axis="0 0 1"/>
      <geom type="box" size="0.1 0.1 0.02" rgba="0.9 0.9 1.0 0.8" friction="0.00 0.00 0.00"/>
    </body>
    <body name="ice_30" pos="0.99 -0.37 0">
      <joint name="ice_30_x" type="slide" axis="1 0 0"/>
      <joint name="ice_30_y" type="slide" axis="0 1 0"/>
      <joint name="ice_30_yaw" type="hinge" axis="0 0 1"/>
      <geom type="box" size="0.1 0.1 0.02" rgba="0.9 0.9 1.0 0.8" friction="0.00 0.00 0.00"/>
    </body>
    <body name="ice_31" pos="-1.97 1.56 0">
      <joint name="ice_31_x" type="slide" axis="1 0 0"/>
      <joint name="ice_31_y" type="slide" axis="0 1 0"/>
      <joint name="ice_31_yaw" type="hinge" axis="0 0 1"/>
      <geom type="box" size="0.1 0.1 0.02" rgba="0.9 0.9 1.0 0.8" friction="0.00 0.00 0.00"/>
    </body>
    <body name="ice_32" pos="0.16 -2.50 0">
      <joint name="ice_32_x" type="slide" axis="1 0 0"/>
      <joint name="ice_32_y" type="slide" axis="0 1 0"/>
      <joint name="ice_32_yaw" type="hinge" axis="0 0 1"/>
      <geom type="box" size="0.1 0.1 0.02" rgba="0.9 0.9 1.0 0.8" friction="0.00 0.00 0.00"/>
    </body>
    <body name="ice_33" pos="2.55 0.09 0">
      <joint name="ice_33_x" type="slide" axis="1 0 0"/>
      <joint name="ice_33_y" type="slide" axis="0 1 0"/>
      <joint name="ice_33_yaw" type="hinge" axis="0 0 1"/>
      <geom type="box" size="0.1 0.1 0.02" rgba="0.9 0.9 1.0 0.8" friction="0.00 0.00 0.00"/>
    </body>
    <body name="ice_34" pos="2.96 -1.73 0">
      <joint name="ice_34_x" type="slide" axis="1 0 0"/>
      <joint name="ice_34_y" type="slide" axis="0 1 0"/>
      <joint name="ice_34_yaw" type="hinge" axis="0 0 1"/>
      <geom type="box" size="0.1 0.1 0.02" rgba="0.9 0.9 1.0 0.8" friction="0.00 0.00 0.00"/>
    </body>
    <body name="ice_35" pos="4.50 -1.36 0">
      <joint name="ice_35_x" type="slide" axis="1 0 0"/>
      <joint name="ice_35_y" type="slide" axis="0 1 0"/>
      <joint name="ice_35_yaw" type="hinge" axis="0 0 1"/>
      <geom type="box" size="0.1 0.1 0.02" rgba="0.9 0.9 1.0 0.8" friction="0.00 0.00 0.00"/>
    </body>
    <body name="ice_36" pos="-2.94 2.19 0">
      <joint name="ice_36_x" type="slide" axis="1 0 0"/>
      <joint name="ice_36_y" type="slide" axis="0 1 0"/>
      <joint name="ice_36_yaw" type="hinge" axis="0 0 1"/>
      <geom type="box" size="0.1 0.1 0.02" rgba="0.9 0.9 1.0 0.8" friction="0.00 0.00 0.00"/>
    </body>
    <body name="ice_37" pos="4.73 0.03 0">
      <joint name="ice_37_x" type="slide" axis="1 0 0"/>
      <joint name="ice_37_y" type="slide" axis="0 1 0"/>
      <joint name="ice_37_yaw" type="hinge" axis="0 0 1"/>
      <geom type="box" size="0.1 0.1 0.02" rgba="0.9 0.9 1.0 0.8" friction="0.00 0.00 0.00"/>
    </body>
    <body name="ice_38" pos="0.79 -1.72 0">
      <joint name="ice_38_x" type="slide" axis="1 0 0"/>
      <joint name="ice_38_y" type="slide" axis="0 1 0"/>
      <joint name="ice_38_yaw" type="hinge" axis="0 0 1"/>
      <geom type="box" size="0.1 0.1 0.02" rgba="0.9 0.9 1.0 0.8" friction="0.00 0.00 0.00"/>
    </body>
    <body name="ice_39" pos="1.50 -0.06 0">
      <joint name="ice_39_x" type="slide" axis="1 0 0"/>
      <joint name="ice_39_y" type="slide" axis="0 1 0"/>
      <joint name="ice_39_yaw" type="hinge" axis="0 0 1"/>
      <geom type="box" size="0.1 0.1 0.02" rgba="0.9 0.9 1.0 0.8" friction="0.00 0.00 0.00"/>
    </body>
    <body name="ice_40" pos="-2.59 -0.08 0">
      <joint name="ice_40_x" type="slide" axis="1 0 0"/>
      <joint name="ice_40_y" type="slide" axis="0 1 0"/>
      <joint name="ice_40_yaw" type="hinge" axis="0 0 1"/>
      <geom type="box" size="0.1 0.1 0.02" rgba="0.9 0.9 1.0 0.8" friction="0.00 0.00 0.00"/>
    </body>
    <body name="ice_41" pos="2.53 -0.73 0">
      <joint name="ice_41_x" type="slide" axis="1 0 0"/>
      <joint name="ice_41_y" type="slide" axis="0 1 0"/>
      <joint name="ice_41_yaw" type="hinge" axis="0 0 1"/>
      <geom type="box" size="0.1 0.1 0.02" rgba="0.9 0.9 1.0 0.8" friction="0.00 0.00 0.00"/>
    </body>
    <body name="ice_42" pos="1.86 -0.64 0">
      <joint name="ice_42_x" type="slide" axis="1 0 0"/>
      <joint name="ice_42_y" type="slide" axis="0 1 0"/>
      <joint name="ice_42_yaw" type="hinge" axis="0 0 1"/>
      <geom type="box" size="0.1 0.1 0.02" rgba="0.9 0.9 1.0 0.8" friction="0.00 0.00 0.00"/>
    </body>
    <body name="ice_43" pos="2.43 -1.28 0">
      <joint name="ice_43_x" type="slide" axis="1 0 0"/>
      <joint name="ice_43_y" type="slide" axis="0 1 0"/>
      <joint name="ice_43_yaw" type="hinge" axis="0 0 1"/>
      <geom type="box" size="0.1 0.1 0.02" rgba="0.9 0.9 1.0 0.8" friction="0.00 0.00 0.00"/>
    </body>
    <body name="ice_44" pos="1.26 0.45 0">
      <joint name="ice_44_x" type="slide" axis="1 0 0"/>
      <joint name="ice_44_y" type="slide" axis="0 1 0"/>
      <joint name="ice_44_yaw" type="hinge" axis="0 0 1"/>
      <geom type="box" size="0.1 0.1 0.02" rgba="0.9 0.9 1.0 0.8" friction="0.00 0.00 0.00"/>
    </body>
    <body name="ice_45" pos="-1.65 0.77 0">
      <joint name="ice_45_x" type="slide" axis="1 0 0"/>
      <joint name="ice_45_y" type="slide" axis="0 1 0"/>
      <joint name="ice_45_yaw" type="hinge" axis="0 0 1"/>
      <geom type="box" size="0.1 0.1 0.02" rgba="0.9 0.9 1.0 0.8" friction="0.00 0.00 0.00"/>
    </body>
    <body name="ice_46" pos="-2.59 -1.27 0">
      <joint name="ice_46_x" type="slide" axis="1 0 0"/>
      <joint name="ice_46_y" type="slide" axis="0 1 0"/>
      <joint name="ice_46_yaw" type="hinge" axis="0 0 1"/>
      <geom type="box" size="0.1 0.1 0.02" rgba="0.9 0.9 1.0 0.8" friction="0.00 0.00 0.00"/>
    </body>
    <body name="ice_47" pos="-4.88 -0.89 0">
      <joint name="ice_47_x" type="slide" axis="1 0 0"/>
      <joint name="ice_47_y" type="slide" axis="0 1 0"/>
      <joint name="ice_47_yaw" type="hinge" axis="0 0 1"/>
      <geom type="box" size="0.1 0.1 0.02" rgba="0.9 0.9 1.0 0.8" friction="0.00 0.00 0.00"/>
    </body>
    <body name="ice_48" pos="0.26 0.50 0">
      <joint name="ice_48_x" type="slide" axis="1 0 0"/>
      <joint name="ice_48_y" type="slide" axis="0 1 0"/>
      <joint name="ice_48_yaw" type="hinge" axis="0 0 1"/>
      <geom type="box" size="0.1 0.1 0.02" rgba="0.9 0.9 1.0 0.8" friction="0.00 0.00 0.00"/>
    </body>
    <body name="ice_49" pos="0.84 -0.65 0">
      <joint name="ice_49_x" type="slide" axis="1 0 0"/>
      <joint name="ice_49_y" type="slide" axis="0 1 0"/>
      <joint name="ice_49_yaw" type="hinge" axis="0 0 1"/>
      <geom type="box" size="0.1 0.1 0.02" rgba="0.9 0.9 1.0 0.8" friction="0.00 0.00 0.00"/>
    </body>
    <body name="ice_50" pos="-1.21 0.90 0">
      <joint name="ice_50_x" type="slide" axis="1 0 0"/>
      <joint name="ice_50_y" type="slide" axis="0 1 0"/>
      <joint name="ice_50_yaw" type="hinge" axis="0 0 1"/>
      <geom type="box" size="0.1 0.1 0.02" rgba="0.9 0.9 1.0 0.8" friction="0.00 0.00 0.00"/>
    </body>
    <body name="ice_51" pos="4.58 0.63 0">
      <joint name="ice_51_x" type="slide" axis="1 0 0"/>
      <joint name="ice_51_y" type="slide" axis="0 1 0"/>
      <joint name="ice_51_yaw" type="hinge" axis="0 0 1"/>
      <geom type="box" size="0.1 0.1 0.02" rgba="0.9 0.9 1.0 0.8" friction="0.00 0.00 0.00"/>
    </body>
    <body name="ice_52" pos="2.02 0.04 0">
      <joint name="ice_52_x" type="slide" axis="1 0 0"/>
      <joint name="ice_52_y" type="slide" axis="0 1 0"/>
      <joint name="ice_52_yaw" type="hinge" axis="0 0 1"/>
      <geom type="box" size="0.1 0.1 0.02" rgba="0.9 0.9 1.0 0.8" friction="0.00 0.00 0.00"/>
    </body>
    <body name="ice_53" pos="3.43 -1.78 0">
      <joint name="ice_53_x" type="slide" axis="1 0 0"/>
      <joint name="ice_53_y" type="slide" axis="0 1 0"/>
      <joint name="ice_53_yaw" type="hinge" axis="0 0 1"/>
      <geom type="box" size="0.1 0.1 0.02" rgba="0.9 0.9 1.0 0.8" friction="0.00 0.00 0.00"/>
    </body>
    <body name="ice_54" pos="2.26 0.49 0">
      <joint name="ice_54_x" type="slide" axis="1 0 0"/>
      <joint name="ice_54_y" type="slide" axis="0 1 0"/>
      <joint name="ice_54_yaw" type="hinge" axis="0 0 1"/>
      <geom type="box" size="0.1 0.1 0.02" rgba="0.9 0.9 1.0 0.8" friction="0.00 0.00 0.00"/>
    </body>
    <body name="ice_55" pos="2.17 0.78 0">
      <joint name="ice_55_x" type="slide" axis="1 0 0"/>
      <joint name="ice_55_y" type="slide" axis="0 1 0"/>
      <joint name="ice_55_yaw" type="hinge" axis="0 0 1"/>
      <geom type="box" size="0.1 0.1 0.02" rgba="0.9 0.9 1.0 0.8" friction="0.00 0.00 0.00"/>
    </body>
    <body name="ice_56" pos="-1.09 -1.75 0">
      <joint name="ice_56_x" type="slide" axis="1 0 0"/>
      <joint name="ice_56_y" type="slide" axis="0 1 0"/>
      <joint name="ice_56_yaw" type="hinge" axis="0 0 1"/>
      <geom type="box" size="0.1 0.1 0.02" rgba="0.9 0.9 1.0 0.8" friction="0.00 0.00 0.00"/>
    </body>
    <body name="ice_57" pos="-2.06 2.43 0">
      <joint name="ice_57_x" type="slide" axis="1 0 0"/>
      <joint name="ice_57_y" type="slide" axis="0 1 0"/>
      <joint name="ice_57_yaw" type="hinge" axis="0 0 1"/>
      <geom type="box" size="0.1 0.1 0.02" rgba="0.9 0.9 1.0 0.8" friction="0.00 0.00 0.00"/>
    </body>
    <body name="ice_58" pos="-2.47 0.91 0">
      <joint name="ice_58_x" type="slide" axis="1 0 0"/>
      <joint name="ice_58_y" type="slide" axis="0 1 0"/>
      <joint name="ice_58_yaw" type="hinge" axis="0 0 1"/>
      <geom type="box" size="0.1 0.1 0.02" rgba="0.9 0.9 1.0 0.8" friction="0.00 0.00 0.00"/>
    </body>
    <body name="ice_59" pos="4.32 0.14 0">
      <joint name="ice_59_x" type="slide" axis="1 0 0"/>
      <joint name="ice_59_y" type="slide" axis="0 1 0"/>
      <joint name="ice_59_yaw" type="hinge" axis="0 0 1"/>
      <geom type="box" size="0.1 0.1 0.02" rgba="0.9 0.9 1.0 0.8" friction="0.00 0.00 0.00"/>
    </body>
    <body name="ice_60" pos="3.83 -0.49 0">
      <joint name="ice_60_x" type="slide" axis="1 0 0"/>
      <joint name="ice_60_y" type="slide" axis="0 1 0"/>
      <joint name="ice_60_yaw" type="hinge" axis="0 0 1"/>
      <geom type="box" size="0.1 0.1 0.02" rgba="0.9 0.9 1.0 0.8" friction="0.00 0.00 0.00"/>
    </body>
    <body name="ice_61" pos="-1.84 1.91 0">
      <joint name="ice_61_x" type="slide" axis="1 0 0"/>
      <joint name="ice_61_y" type="slide" axis="0 1 0"/>
      <joint name="ice_61_yaw" type="hinge" axis="0 0 1"/>
      <geom type="box" size="0.1 0.1 0.02" rgba="0.9 0.9 1.0 0.8" friction="0.00 0.00 0.00"/>
    </body>
    <body name="ice_62" pos="3.80 -2.30 0">
      <joint name="ice_62_x" type="slide" axis="1 0 0"/>
      <joint name="ice_62_y" type="slide" axis="0 1 0"/>
      <joint name="ice_62_yaw" type="hinge" axis="0 0 1"/>
      <geom type="box" size="0.1 0.1 0.02" rgba="0.9 0.9 1.0 0.8" friction="0.00 0.00 0.00"/>
    </body>
    <body name="ice_63" pos="-4.19 1.51 0">
      <joint name="ice_63_x" type="slide" axis="1 0 0"/>
      <joint name="ice_63_y" type="slide" axis="0 1 0"/>
      <joint name="ice_63_yaw" type="hinge" axis="0 0 1"/>
      <geom type="box" size="0.1 0.1 0.02" rgba="0.9 0.9 1.0 0.8" friction="0.00 0.00 0.00"/>
    </body>
    <body name="ice_64" pos="1.40 0.92 0">
      <joint name="ice_64_x" type="slide" axis="1 0 0"/>
      <joint name="ice_64_y" type="slide" axis="0 1 0"/>
      <joint name="ice_64_yaw" type="hinge" axis="0 0 1"/>
      <geom type="box" size="0.1 0.1 0.02" rgba="0.9 0.9 1.0 0.8" friction="0.00 0.00 0.00"/>
    </body>
    <body name="ice_65" pos="0.59 2.47 0">
      <joint name="ice_65_x" type="slide" axis="1 0 0"/>
      <joint name="ice_65_y" type="slide" axis="0 1 0"/>
      <joint name="ice_65_yaw" type="hinge" axis="0 0 1"/>
      <geom type="box" size="0.1 0.1 0.02" rgba="0.9 0.9 1.0 0.8" friction="0.00 0.00 0.00"/>
    </body>
    <body name="ice_66" pos="4.14 -0.73 0">
      <joint name="ice_66_x" type="slide" axis="1 0 0"/>
      <joint name="ice_66_y" type="slide" axis="0 1 0"/>
      <joint name="ice_66_yaw" type="hinge" axis="0 0 1"/>
      <geom type="box" size="0.1 0.1 0.02" rgba="0.9 0.9 1.0 0.8" friction="0.00 0.00 0.00"/>
    </body>
    <body name="ice_67" pos="1.68 1.14 0">
      <joint name="ice_67_x" type="slide" axis="1 0 0"/>
      <joint name="ice_67_y" type="slide" axis="0 1 0"/>
      <joint name="ice_67_yaw" type="hinge" axis="0 0 1"/>
      <geom type="box" size="0.1 0.1 0.02" rgba="0.9 0.9 1.0 0.8" friction="0.00 0.00 0.00"/>
    </body>
    <body name="ice_68" pos="0.55 1.89 0">
      <joint name="ice_68_x" type="slide" axis="1 0 0"/>
      <joint name="ice_68_y" type="slide" axis="0 1 0"/>
      <joint name="ice_68_yaw" type="hinge" axis="0 0 1"/>
      <geom type="box" size="0.1 0.1 0.02" rgba="0.9 0.9 1.0 0.8" friction="0.00 0.00 0.00"/>
    </body>
    <body name="ice_69" pos="-2.88 0.60 0">
      <joint name="ice_69_x" type="slide" axis="1 0 0"/>
      <joint name="ice_69_y" type="slide" axis="0 1 0"/>
      <joint name="ice_69_yaw" type="hinge" axis="0 0 1"/>
      <geom type="box" size="0.1 0.1 0.02" rgba="0.9 0.9 1.0 0.8" friction="0.00 0.00 0.00"/>
    </body>
    <body name="ice_70" pos="0.66 -2.33 0">
      <joint name="ice_70_x" type="slide" axis="1 0 0"/>
      <joint name="ice_70_y" type="slide" axis="0 1 0"/>
      <joint name="ice_70_yaw" type="hinge" axis="0 0 1"/>
      <geom type="box" size="0.1 0.1 0.02" rgba="0.9 0.9 1.0 0.8" friction="0.00 0.00 0.00"/>
    </body>
    <body name="ice_71" pos="-4.03 -0.74 0">
      <joint name="ice_71_x" type="slide" axis="1 0 0"/>
      <joint name="ice_71_y" type="slide" axis="0 1 0"/>
      <joint name="ice_71_yaw" type="hinge" axis="0 0 1"/>
      <geom type="box" size="0.1 0.1 0.02" rgba="0.9 0.9 1.0 0.8" friction="0.00 0.00 0.00"/>
    </body>
    <body name="ice_72" pos="-0.89 -1.27 0">
      <joint name="ice_72_x" type="slide" axis="1 0 0"/>
      <joint name="ice_72_y" type="slide" axis="0 1 0"/>
      <joint name="ice_72_yaw" type="hinge" axis="0 0 1"/>
      <geom type="box" size="0.1 0.1 0.02" rgba="0.9 0.9 1.0 0.8" friction="0.00 0.00 0.00"/>
    </body>
    <body name="ice_73" pos="-4.18 -0.01 0">
      <joint name="ice_73_x" type="slide" axis="1 0 0"/>
      <joint name="ice_73_y" type="slide" axis="0 1 0"/>
      <joint name="ice_73_yaw" type="hinge" axis="0 0 1"/>
      <geom type="box" size="0.1 0.1 0.02" rgba="0.9 0.9 1.0 0.8" friction="0.00 0.00 0.00"/>
    </body>
    <body name="ice_74" pos="3.52 1.83 0">
      <joint name="ice_74_x" type="slide" axis="1 0 0"/>
      <joint name="ice_74_y" type="slide" axis="0 1 0"/>
      <joint name="ice_74_yaw" type="hinge" axis="0 0 1"/>
      <geom type="box" size="0.1 0.1 0.02" rgba="0.9 0.9 1.0 0.8" friction="0.00 0.00 0.00"/>
    </body>
    <body name="ice_75" pos="4.08 -1.86 0">
      <joint name="ice_75_x" type="slide" axis="1 0 0"/>
      <joint name="ice_75_y" type="slide" axis="0 1 0"/>
      <joint name="ice_75_yaw" type="hinge" axis="0 0 1"/>
      <geom type="box" size="0.1 0.1 0.02" rgba="0.9 0.9 1.0 0.8" friction="0.00 0.00 0.00"/>
    </body>
    <body name="ice_76" pos="-2.15 -0.17 0">
      <joint name="ice_76_x" type="slide" axis="1 0 0"/>
      <joint name="ice_76_y" type="slide" axis="0 1 0"/>
      <joint name="ice_76_yaw" type="hinge" axis="0 0 1"/>
      <geom type="box" size="0.1 0.1 0.02" rgba="0.9 0.9 1.0 0.8" friction="0.00 0.00 0.00"/>
    </body>
    <body name="ice_77" pos="-1.91 0.61 0">
      <joint name="ice_77_x" type="slide" axis="1 0 0"/>
      <joint name="ice_77_y" type="slide" axis="0 1 0"/>
      <joint name="ice_77_yaw" type="hinge" axis="0 0 1"/>
      <geom type="box" size="0.1 0.1 0.02" rgba="0.9 0.9 1.0 0.8" friction="0.00 0.00 0.00"/>
    </body>
    <body name="ice_78" pos="-3.56 0.95 0">
      <joint name="ice_78_x" type="slide" axis="1 0 0"/>
      <joint name="ice_78_y" type="slide" axis="0 1 0"/>
      <joint name="ice_78_yaw" type="hinge" axis="0 0 1"/>
      <geom type="box" size="0.1 0.1 0.02" rgba="0.9 0.9 1.0 0.8" friction="0.00 0.00 0.00"/>
    </body>
    <body name="ice_79" pos="2.37 2.16 0">
      <joint name="ice_79_x" type="slide" axis="1 0 0"/>
      <joint name="ice_79_y" type="slide" axis="0 1 0"/>
      <joint name="ice_79_yaw" type="hinge" axis="0 0 1"/>
      <geom type="box" size="0.1 0.1 0.02" rgba="0.9 0.9 1.0 0.8" friction="0.00 0.00 0.00"/>
    </body>
    <body name="ice_80" pos="2.38 1.23 0">
      <joint name="ice_80_x" type="slide" axis="1 0 0"/>
      <joint name="ice_80_y" type="slide" axis="0 1 0"/>
      <joint name="ice_80_yaw" type="hinge" axis="0 0 1"/>
      <geom type="box" size="0.1 0.1 0.02" rgba="0.9 0.9 1.0 0.8" friction="0.00 0.00 0.00"/>
    </body>
    <body name="ice_81" pos="-0.77 -2.25 0">
      <joint name="ice_81_x" type="slide" axis="1 0 0"/>
      <joint name="ice_81_y" type="slide" axis="0 1 0"/>
      <joint name="ice_81_yaw" type="hinge" axis="0 0 1"/>
      <geom type="box" size="0.1 0.1 0.02" rgba="0.9 0.9 1.0 0.8" friction="0.00 0.00 0.00"/>
    </body>
    <body name="ice_82" pos="-2.65 1.81 0">
      <joint name="ice_82_x" type="slide" axis="1 0 0"/>
      <joint name="ice_82_y" type="slide" axis="0 1 0"/>
      <joint name="ice_82_yaw" type="hinge" axis="0 0 1"/>
      <geom type="box" size="0.1 0.1 0.02" rgba="0.9 0.9 1.0 0.8" friction="0.00 0.00 0.00"/>
    </body>
    <body name="ice_83" pos="1.57 -1.02 0">
      <joint name="ice_83_x" type="slide" axis="1 0 0"/>
      <joint name="ice_83_y" type="slide" axis="0 1 0"/>
      <joint name="ice_83_yaw" type="hinge" axis="0 0 1"/>
      <geom type="box" size="0.1 0.1 0.02" rgba="0.9 0.9 1.0 0.8" friction="0.00 0.00 0.00"/>
    </body>
    <body name="ice_84" pos="2.45 0.93 0">
      <joint name="ice_84_x" type="slide" axis="1 0 0"/>
      <joint name="ice_84_y" type="slide" axis="0 1 0"/>
      <joint name="ice_84_yaw" type="hinge" axis="0 0 1"/>
      <geom type="box" size="0.1 0.1 0.02" rgba="0.9 0.9 1.0 0.8" friction="0.00 0.00 0.00"/>
    </body>
    <body name="ice_85" pos="1.81 -1.81 0">
      <joint name="ice_85_x" type="slide" axis="1 0 0"/>
      <joint name="ice_85_y" type="slide" axis="0 1 0"/>
      <joint name="ice_85_yaw" type="hinge" axis="0 0 1"/>
      <geom type="box" size="0.1 0.1 0.02" rgba="0.9 0.9 1.0 0.8" friction="0.00 0.00 0.00"/>
    </body>
    <body name="ice_86" pos="0.67 0.71 0">
      <joint name="ice_86_x" type="slide" axis="1 0 0"/>
      <joint name="ice_86_y" type="slide" axis="0 1 0"/>
      <joint name="ice_86_yaw" type="hinge" axis="0 0 1"/>
      <geom type="box" size="0.1 0.1 0.02" rgba="0.9 0.9 1.0 0.8" friction="0.00 0.00 0.00"/>
    </body>
    <body name="ice_87" pos="-1.50 -1.04 0">
      <joint name="ice_87_x" type="slide" axis="1 0 0"/>
      <joint name="ice_87_y" type="slide" axis="0 1 0"/>
      <joint name="ice_87_yaw" type="hinge" axis="0 0 1"/>
      <geom type="box" size="0.1 0.1 0.02" rgba="0.9 0.9 1.0 0.8" friction="0.00 0.00 0.00"/>
    </body>
    <body name="ice_88" pos="-1.60 -0.25 0">
      <joint name="ice_88_x" type="slide" axis="1 0 0"/>
      <joint name="ice_88_y" type="slide" axis="0 1 0"/>
      <joint name="ice_88_yaw" type="hinge" axis="0 0 1"/>
      <geom type="box" size="0.1 0.1 0.02" rgba="0.9 0.9 1.0 0.8" friction="0.00 0.00 0.00"/>
    </body>
    <body name="ice_89" pos="2.10 -1.35 0">
      <joint name="ice_89_x" type="slide" axis="1 0 0"/>
      <joint name="ice_89_y" type="slide" axis="0 1 0"/>
      <joint name="ice_89_yaw" type="hinge" axis="0 0 1"/>
      <geom type="box" size="0.1 0.1 0.02" rgba="0.9 0.9 1.0 0.8" friction="0.00 0.00 0.00"/>
    </body>
    <body name="ice_90" pos="3.55 0.68 0">
      <joint name="ice_90_x" type="slide" axis="1 0 0"/>
      <joint name="ice_90_y" type="slide" axis="0 1 0"/>
      <joint name="ice_90_yaw" type="hinge" axis="0 0 1"/>
      <geom type="box" size="0.1 0.1 0.02" rgba="0.9 0.9 1.0 0.8" friction="0.00 0.00 0.00"/>
    </body>
    <body name="ice_91" pos="-4.98 -2.05 0">
      <joint name="ice_91_x" type="slide" axis="1 0 0"/>
      <joint name="ice_91_y" type="slide" axis="0 1 0"/>
      <joint name="ice_91_yaw" type="hinge" axis="0 0 1"/>
      <geom type="box" size="0.1 0.1 0.02" rgba="0.9 0.9 1.0 0.8" friction="0.00 0.00 0.00"/>
    </body>
    <body name="ice_92" pos="3.72 2.49 0">
      <joint name="ice_92_x" type="slide" axis="1 0 0"/>
      <joint name="ice_92_y" type="slide" axis="0 1 0"/>
      <joint name="ice_92_yaw" type="hinge" axis="0 0 1"/>
      <geom type="box" size="0.1 0.1 0.02" rgba="0.9 0.9 1.0 0.8" friction="0.00 0.00 0.00"/>
    </body>
    <body name="ice_93" pos="-2.47 -2.06 0">
      <joint name="ice_93_x" type="slide" axis="1 0 0"/>
      <joint name="ice_93_y" type="slide" axis="0 1 0"/>
      <joint name="ice_93_yaw" type="hinge" axis="0 0 1"/>
      <geom type="box" size="0.1 0.1 0.02" rgba="0.9 0.9 1.0 0.8" friction="0.00 0.00 0.00"/>
    </body>
    <body name="ice_94" pos="-4.81 1.62 0">
      <joint name="ice_94_x" type="slide" axis="1 0 0"/>
      <joint name="ice_94_y" type="slide" axis="0 1 0"/>
      <joint name="ice_94_yaw" type="hinge" axis="0 0 1"/>
      <geom type="box" size="0.1 0.1 0.02" rgba="0.9 0.9 1.0 0.8" friction="0.00 0.00 0.00"/>
    </body>
    <body name="ice_95" pos="4.83 1.13 0">
      <joint name="ice_95_x" type="slide" axis="1 0 0"/>
      <joint name="ice_95_y" type="slide" axis="0 1 0"/>
      <joint name="ice_95_yaw" type="hinge" axis="0 0 1"/>
      <geom type="box" size="0.1 0.1 0.02" rgba="0.9 0.9 1.0 0.8" friction="0.00 0.00 0.00"/>
    </body>
    <body name="ice_96" pos="-2.24 0.23 0">
      <joint name="ice_96_x" type="slide" axis="1 0 0"/>
      <joint name="ice_96_y" type="slide" axis="0 1 0"/>
      <joint name="ice_96_yaw" type="hinge" axis="0 0 1"/>
      <geom type="box" size="0.1 0.1 0.02" rgba="0.9 0.9 1.0 0.8" friction="0.00 0.00 0.00"/>
    </body>
    <body name="ice_97" pos="-1.93 -0.45 0">
      <joint name="ice_97_x" type="slide" axis="1 0 0"/>
      <joint name="ice_97_y" type="slide" axis="0 1 0"/>
      <joint name="ice_97_yaw" type="hinge" axis="0 0 1"/>
      <geom type="box" size="0.1 0.1 0.02" rgba="0.9 0.9 1.0 0.8" friction="0.00 0.00 0.00"/>
    </body>
    <body name="ice_98" pos="0.24 -1.87 0">
      <joint name="ice_98_x" type="slide" axis="1 0 0"/>
      <joint name="ice_98_y" type="slide" axis="0 1 0"/>
      <joint name="ice_98_yaw" type="hinge" axis="0 0 1"/>
      <geom type="box" size="0.1 0.1 0.02" rgba="0.9 0.9 1.0 0.8" friction="0.00 0.00 0.00"/>
    </body>
    <body name="ice_99" pos="3.19 -0.94 0">
      <joint name="ice_99_x" type="slide" axis="1 0 0"/>
      <joint name="ice_99_y" type="slide" axis="0 1 0"/>
      <joint name="ice_99_yaw" type="hinge" axis="0 0 1"/>
      <geom type="box" size="0.1 0.1 0.02" rgba="0.9 0.9 1.0 0.8" friction="0.00 0.00 0.00"/>
    </body>
    <body name="ice_100" pos="0.78 1.11 0">
      <joint name="ice_100_x" type="slide" axis="1 0 0"/>
      <joint name="ice_100_y" type="slide" axis="0 1 0"/>
      <joint name="ice_100_yaw" type="hinge" axis="0 0 1"/>
      <geom type="box" size="0.1 0.1 0.02" rgba="0.9 0.9 1.0 0.8" friction="0.00 0.00 0.00"/>
    </body>
    <body name="ice_101" pos="2.74 0.40 0">
      <joint name="ice_101_x" type="slide" axis="1 0 0"/>
      <joint name="ice_101_y" type="slide" axis="0 1 0"/>
      <joint name="ice_101_yaw" type="hinge" axis="0 0 1"/>
      <geom type="box" size="0.1 0.1 0.02" rgba="0.9 0.9 1.0 0.8" friction="0.00 0.00 0.00"/>
    </body>
    <body name="ice_102" pos="-3.48 -1.47 0">
      <joint name="ice_102_x" type="slide" axis="1 0 0"/>
      <joint name="ice_102_y" type="slide" axis="0 1 0"/>
      <joint name="ice_102_yaw" type="hinge" axis="0 0 1"/>
      <geom type="box" size="0.1 0.1 0.02" rgba="0.9 0.9 1.0 0.8" friction="0.00 0.00 0.00"/>
    </body>
    <body name="ice_103" pos="-4.55 -1.97 0">
      <joint name="ice_103_x" type="slide" axis="1 0 0"/>
      <joint name="ice_103_y" type="slide" axis="0 1 0"/>
      <joint name="ice_103_yaw" type="hinge" axis="0 0 1"/>
      <geom type="box" size="0.1 0.1 0.02" rgba="0.9 0.9 1.0 0.8" friction="0.00 0.00 0.00"/>
    </body>
    <body name="ice_104" pos="2.53 -2.20 0">
      <joint name="ice_104_x" type="slide" axis="1 0 0"/>
      <joint name="ice_104_y" type="slide" axis="0 1 0"/>
      <joint name="ice_104_yaw" type="hinge" axis="0 0 1"/>
      <geom type="box" size="0.1 0.1 0.02" rgba="0.9 0.9 1.0 0.8" friction="0.00 0.00 0.00"/>
    </body>
    <body name="ice_105" pos="-0.12 -0.95 0">
      <joint name="ice_105_x" type="slide" axis="1 0 0"/>
      <joint name="ice_105_y" type="slide" axis="0 1 0"/>
      <joint name="ice_105_yaw" type="hinge" axis="0 0 1"/>
      <geom type="box" size="0.1 0.1 0.02" rgba="0.9 0.9 1.0 0.8" friction="0.00 0.00 0.00"/>
    </body>
    <body name="ice_106" pos="-1.72 0.15 0">
      <joint name="ice_106_x" type="slide" axis="1 0 0"/>
      <joint name="ice_106_y" type="slide" axis="0 1 0"/>
      <joint name="ice_106_yaw" type="hinge" axis="0 0 1"/>
      <geom type="box" size="0.1 0.1 0.02" rgba="0.9 0.9 1.0 0.8" friction="0.00 0.00 0.00"/>
    </body>
    <body name="ice_107" pos="-0.93 -0.08 0">
      <joint name="ice_107_x" type="slide" axis="1 0 0"/>
      <joint name="ice_107_y" type="slide" axis="0 1 0"/>
      <joint name="ice_107_yaw" type="hinge" axis="0 0 1"/>
      <geom type="box" size="0.1 0.1 0.02" rgba="0.9 0.9 1.0 0.8" friction="0.00 0.00 0.00"/>
    </body>
    <body name="ice_108" pos="-2.80 -0.61 0">
      <joint name="ice_108_x" type="slide" axis="1 0 0"/>
      <joint name="ice_108_y" type="slide" axis="0 1 0"/>
      <joint name="ice_108_yaw" type="hinge" axis="0 0 1"/>
      <geom type="box" size="0.1 0.1 0.02" rgba="0.9 0.9 1.0 0.8" friction="0.00 0.00 0.00"/>
    </body>
    <body name="ice_109" pos="3.30 -0.16 0">
      <joint name="ice_109_x" type="slide" axis="1 0 0"/>
      <joint name="ice_109_y" type="slide" axis="0 1 0"/>
      <joint name="ice_109_yaw" type="hinge" axis="0 0 1"/>
      <geom type="box" size="0.1 0.1 0.02" rgba="0.9 0.9 1.0 0.8" friction="0.00 0.00 0.00"/>
    </body>
    <body name="ice_110" pos="-0.93 0.67 0">
      <joint name="ice_110_x" type="slide" axis="1 0 0"/>
      <joint name="ice_110_y" type="slide" axis="0 1 0"/>
      <joint name="ice_110_yaw" type="hinge" axis="0 0 1"/>
      <geom type="box" size="0.1 0.1 0.02" rgba="0.9 0.9 1.0 0.8" friction="0.00 0.00 0.00"/>
    </body>
    <body name="ice_111" pos="-0.20 -1.69 0">
      <joint name="ice_111_x" type="slide" axis="1 0 0"/>
      <joint name="ice_111_y" type="slide" axis="0 1 0"/>
      <joint name="ice_111_yaw" type="hinge" axis="0 0 1"/>
      <geom type="box" size="0.1 0.1 0.02" rgba="0.9 0.9 1.0 0.8" friction="0.00 0.00 0.00"/>
    </body>
    <body name="ice_112" pos="-4.40 0.70 0">
      <joint name="ice_112_x" type="slide" axis="1 0 0"/>
      <joint name="ice_112_y" type="slide" axis="0 1 0"/>
      <joint name="ice_112_yaw" type="hinge" axis="0 0 1"/>
      <geom type="box" size="0.1 0.1 0.02" rgba="0.9 0.9 1.0 0.8" friction="0.00 0.00 0.00"/>
    </body>
    <body name="ice_113" pos="-3.59 0.28 0">
      <joint name="ice_113_x" type="slide" axis="1 0 0"/>
      <joint name="ice_113_y" type="slide" axis="0 1 0"/>
      <joint name="ice_113_yaw" type="hinge" axis="0 0 1"/>
      <geom type="box" size="0.1 0.1 0.02" rgba="0.9 0.9 1.0 0.8" friction="0.00 0.00 0.00"/>
    </body>
    <body name="ice_114" pos="-0.60 0.79 0">
      <joint name="ice_114_x" type="slide" axis="1 0 0"/>
      <joint name="ice_114_y" type="slide" axis="0 1 0"/>
      <joint name="ice_114_yaw" type="hinge" axis="0 0 1"/>
      <geom type="box" size="0.1 0.1 0.02" rgba="0.9 0.9 1.0 0.8" friction="0.00 0.00 0.00"/>
    </body>
    <body name="ice_115" pos="2.65 -1.63 0">
      <joint name="ice_115_x" type="slide" axis="1 0 0"/>
      <joint name="ice_115_y" type="slide" axis="0 1 0"/>
      <joint name="ice_115_yaw" type="hinge" axis="0 0 1"/>
      <geom type="box" size="0.1 0.1 0.02" rgba="0.9 0.9 1.0 0.8" friction="0.00 0.00 0.00"/>
    </body>
    <body name="ice_116" pos="0.44 -1.62 0">
      <joint name="ice_116_x" type="slide" axis="1 0 0"/>
      <joint name="ice_116_y" type="slide" axis="0 1 0"/>
      <joint name="ice_116_yaw" type="hinge" axis="0 0 1"/>
      <geom type="box" size="0.1 0.1 0.02" rgba="0.9 0.9 1.0 0.8" friction="0.00 0.00 0.00"/>
    </body>
    <body name="ice_117" pos="-0.64 0.25 0">
      <joint name="ice_117_x" type="slide" axis="1 0 0"/>
      <joint name="ice_117_y" type="slide" axis="0 1 0"/>
      <joint name="ice_117_yaw" type="hinge" axis="0 0 1"/>
      <geom type="box" size="0.1 0.1 0.02" rgba="0.9 0.9 1.0 0.8" friction="0.00 0.00 0.00"/>
    </body>
    <body name="ice_118" pos="-3.94 -2.21 0">
      <joint name="ice_118_x" type="slide" axis="1 0 0"/>
      <joint name="ice_118_y" type="slide" axis="0 1 0"/>
      <joint name="ice_118_yaw" type="hinge" axis="0 0 1"/>
      <geom type="box" size="0.1 0.1 0.02" rgba="0.9 0.9 1.0 0.8" friction="0.00 0.00 0.00"/>
    </body>
    <body name="ice_119" pos="4.52 -0.68 0">
      <joint name="ice_119_x" type="slide" axis="1 0 0"/>
      <joint name="ice_119_y" type="slide" axis="0 1 0"/>
      <joint name="ice_119_yaw" type="hinge" axis="0 0 1"/>
      <geom type="box" size="0.1 0.1 0.02" rgba="0.9 0.9 1.0 0.8" friction="0.00 0.00 0.00"/>
    </body>
    <body name="ice_120" pos="-0.28 1.38 0">
      <joint name="ice_120_x" type="slide" axis="1 0 0"/>
      <joint name="ice_120_y" type="slide" axis="0 1 0"/>
      <joint name="ice_120_yaw" type="hinge" axis="0 0 1"/>
      <geom type="box" size="0.1 0.1 0.02" rgba="0.9 0.9 1.0 0.8" friction="0.00 0.00 0.00"/>
    </body>
    <body name="ice_121" pos="0.63 0.19 0">
      <joint name="ice_121_x" type="slide" axis="1 0 0"/>
      <joint name="ice_121_y" type="slide" axis="0 1 0"/>
      <joint name="ice_121_yaw" type="hinge" axis="0 0 1"/>
      <geom type="box" size="0.1 0.1 0.02" rgba="0.9 0.9 1.0 0.8" friction="0.00 0.00 0.00"/>
    </body>
    <body name="ice_122" pos="-3.48 -0.19 0">
      <joint name="ice_122_x" type="slide" axis="1 0 0"/>
      <joint name="ice_122_y" type="slide" axis="0 1 0"/>
      <joint name="ice_122_yaw" type="hinge" axis="0 0 1"/>
      <geom type="box" size="0.1 0.1 0.02" rgba="0.9 0.9 1.0 0.8" friction="0.00 0.00 0.00"/>
    </body>
    <body name="ice_123" pos="4.04 2.39 0">
      <joint name="ice_123_x" type="slide" axis="1 0 0"/>
      <joint name="ice_123_y" type="slide" axis="0 1 0"/>
      <joint name="ice_123_yaw" type="hinge" axis="0 0 1"/>
      <geom type="box" size="0.1 0.1 0.02" rgba="0.9 0.9 1.0 0.8" friction="0.00 0.00 0.00"/>
    </body>
    <body name="ice_124" pos="-2.14 -1.85 0">
      <joint name="ice_124_x" type="slide" axis="1 0 0"/>
      <joint name="ice_124_y" type="slide" axis="0 1 0"/>
      <joint name="ice_124_yaw" type="hinge" axis="0 0 1"/>
      <geom type="box" size="0.1 0.1 0.02" rgba="0.9 0.9 1.0 0.8" friction="0.00 0.00 0.00"/>
    </body>
    <body name="ice_125" pos="-1.11 1.36 0">
      <joint name="ice_125_x" type="slide" axis="1 0 0"/>
      <joint name="ice_125_y" type="slide" axis="0 1 0"/>
      <joint name="ice_125_yaw" type="hinge" axis="0 0 1"/>
      <geom type="box" size="0.1 0.1 0.02" rgba="0.9 0.9 1.0 0.8" friction="0.00 0.00 0.00"/>
    </body>
    <body name="ice_126" pos="-4.07 -0.33 0">
      <joint name="ice_126_x" type="slide" axis="1 0 0"/>
      <joint name="ice_126_y" type="slide" axis="0 1 0"/>
      <joint name="ice_126_yaw" type="hinge" axis="0 0 1"/>
      <geom type="box" size="0.1 0.1 0.02" rgba="0.9 0.9 1.0 0.8" friction="0.00 0.00 0.00"/>
    </body>
    <body name="ice_127" pos="-4.15 -1.04 0">
      <joint name="ice_127_x" type="slide" axis="1 0 0"/>
      <joint name="ice_127_y" type="slide" axis="0 1 0"/>
      <joint name="ice_127_yaw" type="hinge" axis="0 0 1"/>
      <geom type="box" size="0.1 0.1 0.02" rgba="0.9 0.9 1.0 0.8" friction="0.00 0.00 0.00"/>
    </body>
    <body name="ice_128" pos="4.92 -0.63 0">
      <joint name="ice_128_x" type="slide" axis="1 0 0"/>
      <joint name="ice_128_y" type="slide" axis="0 1 0"/>
      <joint name="ice_128_yaw" type="hinge" axis="0 0 1"/>
      <geom type="box" size="0.1 0.1 0.02" rgba="0.9 0.9 1.0 0.8" friction="0.00 0.00 0.00"/>
    </body>
    <body name="ice_129" pos="4.19 1.75 0">
      <joint name="ice_129_x" type="slide" axis="1 0 0"/>
      <joint name="ice_129_y" type="slide" axis="0 1 0"/>
      <joint name="ice_129_yaw" type="hinge" axis="0 0 1"/>
      <geom type="box" size="0.1 0.1 0.02" rgba="0.9 0.9 1.0 0.8" friction="0.00 0.00 0.00"/>
    </body>
    <body name="ice_130" pos="0.70 -0.97 0">
      <joint name="ice_130_x" type="slide" axis="1 0 0"/>
      <joint name="ice_130_y" type="slide" axis="0 1 0"/>
      <joint name="ice_130_yaw" type="hinge" axis="0 0 1"/>
      <geom type="box" size="0.1 0.1 0.02" rgba="0.9 0.9 1.0 0.8" friction="0.00 0.00 0.00"/>
    </body>
    <body name="ice_131" pos="-4.39 1.18 0">
      <joint name="ice_131_x" type="slide" axis="1 0 0"/>
      <joint name="ice_131_y" type="slide" axis="0 1 0"/>
      <joint name="ice_131_yaw" type="hinge" axis="0 0 1"/>
      <geom type="box" size="0.1 0.1 0.02" rgba="0.9 0.9 1.0 0.8" friction="0.00 0.00 0.00"/>
    </body>
    <body name="ice_132" pos="2.97 1.90 0">
      <joint name="ice_132_x" type="slide" axis="1 0 0"/>
      <joint name="ice_132_y" type="slide" axis="0 1 0"/>
      <joint name="ice_132_yaw" type="hinge" axis="0 0 1"/>
      <geom type="box" size="0.1 0.1 0.02" rgba="0.9 0.9 1.0 0.8" friction="0.00 0.00 0.00"/>
    </body>
    <body name="ice_133" pos="2.95 1.30 0">
      <joint name="ice_133_x" type="slide" axis="1 0 0"/>
      <joint name="ice_133_y" type="slide" axis="0 1 0"/>
      <joint name="ice_133_yaw" type="hinge" axis="0 0 1"/>
      <geom type="box" size="0.1 0.1 0.02" rgba="0.9 0.9 1.0 0.8" friction="0.00 0.00 0.00"/>
    </body>
    <body name="ice_134" pos="-0.52 -1.70 0">
      <joint name="ice_134_x" type="slide" axis="1 0 0"/>
      <joint name="ice_134_y" type="slide" axis="0 1 0"/>
      <joint name="ice_134_yaw" type="hinge" axis="0 0 1"/>
      <geom type="box" size="0.1 0.1 0.02" rgba="0.9 0.9 1.0 0.8" friction="0.00 0.00 0.00"/>
    </body>
    <body name="ice_135" pos="-3.26 1.06 0">
      <joint name="ice_135_x" type="slide" axis="1 0 0"/>
      <joint name="ice_135_y" type="slide" axis="0 1 0"/>
      <joint name="ice_135_yaw" type="hinge" axis="0 0 1"/>
      <geom type="box" size="0.1 0.1 0.02" rgba="0.9 0.9 1.0 0.8" friction="0.00 0.00 0.00"/>
    </body>
    <body name="ice_136" pos="-1.55 -1.53 0">
      <joint name="ice_136_x" type="slide" axis="1 0 0"/>
      <joint name="ice_136_y" type="slide" axis="0 1 0"/>
      <joint name="ice_136_yaw" type="hinge" axis="0 0 1"/>
      <geom type="box" size="0.1 0.1 0.02" rgba="0.9 0.9 1.0 0.8" friction="0.00 0.00 0.00"/>
    </body>
    <body name="ice_137" pos="0.06 -2.15 0">
      <joint name="ice_137_x" type="slide" axis="1 0 0"/>
      <joint name="ice_137_y" type="slide" axis="0 1 0"/>
      <joint name="ice_137_yaw" type="hinge" axis="0 0 1"/>
      <geom type="box" size="0.1 0.1 0.02" rgba="0.9 0.9 1.0 0.8" friction="0.00 0.00 0.00"/>
    </body>
    <body name="ice_138" pos="-4.73 1.92 0">
      <joint name="ice_138_x" type="slide" axis="1 0 0"/>
      <joint name="ice_138_y" type="slide" axis="0 1 0"/>
      <joint name="ice_138_yaw" type="hinge" axis="0 0 1"/>
      <geom type="box" size="0.1 0.1 0.02" rgba="0.9 0.9 1.0 0.8" friction="0.00 0.00 0.00"/>
    </body>
    <body name="ice_139" pos="4.19 -0.27 0">
      <joint name="ice_139_x" type="slide" axis="1 0 0"/>
      <joint name="ice_139_y" type="slide" axis="0 1 0"/>
      <joint name="ice_139_yaw" type="hinge" axis="0 0 1"/>
      <geom type="box" size="0.1 0.1 0.02" rgba="0.9 0.9 1.0 0.8" friction="0.00 0.00 0.00"/>
    </body>
    <body name="ice_140" pos="0.30 -1.05 0">
      <joint name="ice_140_x" type="slide" axis="1 0 0"/>
      <joint name="ice_140_y" type="slide" axis="0 1 0"/>
      <joint name="ice_140_yaw" type="hinge" axis="0 0 1"/>
      <geom type="box" size="0.1 0.1 0.02" rgba="0.9 0.9 1.0 0.8" friction="0.00 0.00 0.00"/>
    </body>
    <body name="ice_141" pos="-3.20 -1.28 0">
      <joint name="ice_141_x" type="slide" axis="1 0 0"/>
      <joint name="ice_141_y" type="slide" axis="0 1 0"/>
      <joint name="ice_141_yaw" type="hinge" axis="0 0 1"/>
      <geom type="box" size="0.1 0.1 0.02" rgba="0.9 0.9 1.0 0.8" friction="0.00 0.00 0.00"/>
    </body>
    <body name="ice_142" pos="-4.14 -1.82 0">
      <joint name="ice_142_x" type="slide" axis="1 0 0"/>
      <joint name="ice_142_y" type="slide" axis="0 1 0"/>
      <joint name="ice_142_yaw" type="hinge" axis="0 0 1"/>
      <geom type="box" size="0.1 0.1 0.02" rgba="0.9 0.9 1.0 0.8" friction="0.00 0.00 0.00"/>
    </body>
    <body name="ice_143" pos="3.08 -1.26 0">
      <joint name="ice_143_x" type="slide" axis="1 0 0"/>
      <joint name="ice_143_y" type="slide" axis="0 1 0"/>
      <joint name="ice_143_yaw" type="hinge" axis="0 0 1"/>
      <geom type="box" size="0.1 0.1 0.02" rgba="0.9 0.9 1.0 0.8" friction="0.00 0.00 0.00"/>
    </body>
    <body name="ice_144" pos="0.17 1.76 0">
      <joint name="ice_144_x" type="slide" axis="1 0 0"/>
      <joint name="ice_144_y" type="slide" axis="0 1 0"/>
      <joint name="ice_144_yaw" type="hinge" axis="0 0 1"/>
      <geom type="box" size="0.1 0.1 0.02" rgba="0.9 0.9 1.0 0.8" friction="0.00 0.00 0.00"/>
    </body>
    <body name="ice_145" pos="-1.64 -1.81 0">
      <joint name="ice_145_x" type="slide" axis="1 0 0"/>
      <joint name="ice_145_y" type="slide" axis="0 1 0"/>
      <joint name="ice_145_yaw" type="hinge" axis="0 0 1"/>
      <geom type="box" size="0.1 0.1 0.02" rgba="0.9 0.9 1.0 0.8" friction="0.00 0.00 0.00"/>
    </body>
    <body name="ice_146" pos="-1.58 1.70 0">
      <joint name="ice_146_x" type="slide" axis="1 0 0"/>
      <joint name="ice_146_y" type="slide" axis="0 1 0"/>
      <joint name="ice_146_yaw" type="hinge" axis="0 0 1"/>
      <geom type="box" size="0.1 0.1 0.02" rgba="0.9 0.9 1.0 0.8" friction="0.00 0.00 0.00"/>
    </body>
    <body name="ice_147" pos="-1.10 1.92 0">
      <joint name="ice_147_x" type="slide" axis="1 0 0"/>
      <joint name="ice_147_y" type="slide" axis="0 1 0"/>
      <joint name="ice_147_yaw" type="hinge" axis="0 0 1"/>
      <geom type="box" size="0.1 0.1 0.02" rgba="0.9 0.9 1.0 0.8" friction="0.00 0.00 0.00"/>
    </body>
    <body name="ice_148" pos="1.40 1.43 0">
      <joint name="ice_148_x" type="slide" axis="1 0 0"/>
      <joint name="ice_148_y" type="slide" axis="0 1 0"/>
      <joint name="ice_148_yaw" type="hinge" axis="0 0 1"/>
      <geom type="box" size="0.1 0.1 0.02" rgba="0.9 0.9 1.0 0.8" friction="0.00 0.00 0.00"/>
    </body>
    <body name="ice_149" pos="-0.03 2.18 0">
      <joint name="ice_149_x" type="slide" axis="1 0 0"/>
      <joint name="ice_149_y" type="slide" axis="0 1 0"/>
      <joint name="ice_149_yaw" type="hinge" axis="0 0 1"/>
      <geom type="box" size="0.1 0.1 0.02" rgba="0.9 0.9 1.0 0.8" friction="0.00 0.00 0.00"/>
    </body>
    <body name="ice_150" pos="-3.34 1.85 0">
      <joint name="ice_150_x" type="slide" axis="1 0 0"/>
      <joint name="ice_150_y" type="slide" axis="0 1 0"/>
      <joint name="ice_150_yaw" type="hinge" axis="0 0 1"/>
      <geom type="box" size="0.1 0.1 0.02" rgba="0.9 0.9 1.0 0.8" friction="0.00 0.00 0.00"/>
    </body>
    <body name="ice_151" pos="2.19 1.62 0">
      <joint name="ice_151_x" type="slide" axis="1 0 0"/>
      <joint name="ice_151_y" type="slide" axis="0 1 0"/>
      <joint name="ice_151_yaw" type="hinge" axis="0 0 1"/>
      <geom type="box" size="0.1 0.1 0.02" rgba="0.9 0.9 1.0 0.8" friction="0.00 0.00 0.00"/>
    </body>
    <body name="ice_152" pos="-1.54 1.22 0">
      <joint name="ice_152_x" type="slide" axis="1 0 0"/>
      <joint name="ice_152_y" type="slide" axis="0 1 0"/>
      <joint name="ice_152_yaw" type="hinge" axis="0 0 1"/>
      <geom type="box" size="0.1 0.1 0.02" rgba="0.9 0.9 1.0 0.8" friction="0.00 0.00 0.00"/>
    </body>
    <body name="ice_153" pos="-3.88 -1.54 0">
      <joint name="ice_153_x" type="slide" axis="1 0 0"/>
      <joint name="ice_153_y" type="slide" axis="0 1 0"/>
      <joint name="ice_153_yaw" type="hinge" axis="0 0 1"/>
      <geom type="box" size="0.1 0.1 0.02" rgba="0.9 0.9 1.0 0.8" friction="0.00 0.00 0.00"/>
    </body>
    <body name="ice_154" pos="0.17 0.95 0">
      <joint name="ice_154_x" type="slide" axis="1 0 0"/>
      <joint name="ice_154_y" type="slide" axis="0 1 0"/>
      <joint name="ice_154_yaw" type="hinge" axis="0 0 1"/>
      <geom type="box" size="0.1 0.1 0.02" rgba="0.9 0.9 1.0 0.8" friction="0.00 0.00 0.00"/>
    </body>
    <body name="ice_155" pos="-2.99 -2.13 0">
      <joint name="ice_155_x" type="slide" axis="1 0 0"/>
      <joint name="ice_155_y" type="slide" axis="0 1 0"/>
      <joint name="ice_155_yaw" type="hinge" axis="0 0 1"/>
      <geom type="box" size="0.1 0.1 0.02" rgba="0.9 0.9 1.0 0.8" friction="0.00 0.00 0.00"/>
    </body>
    <body name="ice_156" pos="-4.81 1.24 0">
      <joint name="ice_156_x" type="slide" axis="1 0 0"/>
      <joint name="ice_156_y" type="slide" axis="0 1 0"/>
      <joint name="ice_156_yaw" type="hinge" axis="0 0 1"/>
      <geom type="box" size="0.1 0.1 0.02" rgba="0.9 0.9 1.0 0.8" friction="0.00 0.00 0.00"/>
    </body>
    <body name="ice_157" pos="1.04 0.94 0">
      <joint name="ice_157_x" type="slide" axis="1 0 0"/>
      <joint name="ice_157_y" type="slide" axis="0 1 0"/>
      <joint name="ice_157_yaw" type="hinge" axis="0 0 1"/>
      <geom type="box" size="0.1 0.1 0.02" rgba="0.9 0.9 1.0 0.8" friction="0.00 0.00 0.00"/>
    </body>
    <body name="ice_158" pos="-0.44 -0.52 0">
      <joint name="ice_158_x" type="slide" axis="1 0 0"/>
      <joint name="ice_158_y" type="slide" axis="0 1 0"/>
      <joint name="ice_158_yaw" type="hinge" axis="0 0 1"/>
      <geom type="box" size="0.1 0.1 0.02" rgba="0.9 0.9 1.0 0.8" friction="0.00 0.00 0.00"/>
    </body>
    <body name="ice_159" pos="1.98 1.38 0">
      <joint name="ice_159_x" type="slide" axis="1 0 0"/>
      <joint name="ice_159_y" type="slide" axis="0 1 0"/>
      <joint name="ice_159_yaw" type="hinge" axis="0 0 1"/>
      <geom type="box" size="0.1 0.1 0.02" rgba="0.9 0.9 1.0 0.8" friction="0.00 0.00 0.00"/>
    </body>
  </worldbody>

  <actuator>
    <motor name="asv_forward" joint="asv_x" ctrlrange="-200 200" gear="1"/>
    <motor joint="asv_yaw" name="asv_rudder" ctrlrange="-1 1" gear="5"/>  
  </actuator>
</mujoco>